Workbook

Sheet Cover
B2: Air Asia
B4: Modelled by Peter Hopkinson
B5: =DATE(2026, 10, 3) -> 46298

Sheet Assumptions
B2: Air Asia Group
B3: Forecast Assumptions | 2026F-2030F
B5: SECTION A - STATIC ASSUMPTIONS
B7: A1. Fleet and Operating Parameters
B9: Fleet Capacity | D9: 247
B10: Operating days | D10: 365
B11: Flights per day | D11: 3
B12: Average Aircraft Size | D12: 320
B13: Average Flight Distance | D13: 1200
B14: Aircraft Capacity | D14: 0.975
B16: A2. Aircraft Leases & ROU Assets
B18: Initial New Aircraft Cost | D18: 20
B19: Term | D19: 10
B20: Discount Rate | D20: 0.06
B22: A3. PP&E, Intangibles, Lease & Maintenance
B24: PP&E useful life | D24: 7
B25: Finite Intangible asset life | D25: 10
B26: Lease liabilities average contract life | D26: 5.6
B27: Intangible Additions - % of Revenue | D27: 0.0075
B28: Maintenance provision per aircraft | D28: 0.75
B29: Maintenance provision utilization | D29: 0.035
B31: A4. Financial Policy & Liquidity
B33: Target dividend payout ratio | D33: 0.3
B34: Share buyback ratio | D34: 0
B35: Minimum cash requirement | D35: 1500
B36: Minimum net income requirememt | D36: 250
B37: Opening share count | D37: 3360826386
B38: Current share price | D38: 0.475
B40: SECTION B - TEMPORAL / FORECAST ASSUMPTIONS
D43: 2024 | E43: 2025 | F43: =E43+1 -> 2026 | G43: =F43+1 -> 2027 | H43: =G43+1 -> 2028 | I43: =H43+1 -> 2029 | J43: =I43+1 -> 2030
D44: PF = Pro forma | J44: F = Forecast
B46: B1. Macro Assumptions
B48: Inflation | F48: 0.045 | G48: 0.04 | H48: 0.035 | I48: 0.03 | J48: 0.03
B49: Southeast Asia real GDP growth | C49: % | D49: 0.048 | E49: 0.045 | F49: 0.047 | G49: 0.049 | H49: 0.045 | I49: 0.045 | J49: 0.045
B50: Fuel Prices | E50: 102 | F50: 150 | G50: 110 | H50: 100 | I50: 100 | J50: 100
B51: Hedged Fuel Spread | F51: 5 | G51: 5 | H51: 5 | I51: 5 | J51: 5
B52: Hedged Fuel Price | F52: =E50+F51 -> 107 | G52: =F50+5 -> 155 | H52: =G50+5 -> 115 | I52: =H50+5 -> 105 | J52: =I50+5 -> 105
B53: Hedge Ratio | F53: 0.5 | G53: 0.5 | H53: 0.5 | I53: 0.5 | J53: 0.5
B55: B2. Passenger demand and Capacity Constraints
B57: Passenger growth | C57: % | F57: 0.06 | G57: 0.06 | H57: 0.06 | I57: 0.06 | J57: 0.06
...

Sheet Model
B2: Air Asia Group
B3: Financial Statements - Income Statement
B5: RM millions, unless otherwise stated
E7: 2024 | F7: 2025 | G7: =F7+1 -> 2026 | H7: =G7+1 -> 2027 | I7: =H7+1 -> 2028 | J7: =I7+1 -> 2029 | K7: =J7+1 -> 2030
E8: PF = Pro forma | K8: F = Forecast
B10: Revenue | E10: 22181 | F10: 22221 | G10: =G231 -> 24370.593 | H10: =H231 -> 26600.522 | I10: =I231 -> 28895.027 | J10: =J231 -> 31235.842 | K10: =K231 -> 33766.403
B11: Staff cost | E11: -2376 | F11: -2455 | G11: =-G290 -> -2632.8187 | H11: =-H290 -> -2867.8324 | I11: =-I290 -> -3060.6776 | J11: =-J290 -> -3468.9197 | K11: =-K290 -> -4013.9345
B12: Aircraft fuel expenses | E12: -8610 | F12: -7691 | G12: =-G281 -> -10854.289 | H12: =-H281 -> -11651.803 | I12: =-I281 -> -9863.5541 | J12: =-J281 -> -10098.143 | K12: =-K281 -> -11360.41
B13: Maintenance and overhaul | E13: -4458 | F13: -3444 | G13: =-G292 -> -3547.9823 | H13: =-H292 -> -3841.4376 | I13: =-I292 -> -4148.4117 | J13: =-J292 -> -4587.8767 | K13: =-K292 -> -5316.2021
B14: User charges | E14: -3666 | F14: -3206 | G14: =-G296 -> -3485.5984 | H14: =-H296 -> -3773.8939 | I14: =-I296 -> -4075.4705 | J14: =-J296 -> -4507.2084 | K14: =-K296 -> -5222.7277
B15: Other operating expenses | E15: -1581 | F15: -1044 | G15: =-G301 -> -1144.9934 | H15: =-H301 -> -1249.7613 | I15: =-I301 -> -1357.563 | J15: =-J301 -> -1467.5405 | K15: =-K301 -> -1586.4329
B16: Operating expenses | E16: =SUM(E11:E15) -> -20691 | F16: =SUM(F11:F15) -> -17840 | G16: =SUM(G11:G15) -> -21665.682 | H16: =SUM(H11:H15) -> -23384.728 | I16: =SUM(I11:I15) -> -22505.677 | J16: =SUM(J11:J15) -> -24129.688 | K16: =SUM(K11:K15) -> -27499.708
B17: Other income | E17: 1236 | F17: 179 | G17: =F17 -> 179 | H17: =G17 -> 179 | I17: =H17 -> 179 | J17: =I17 -> 179 | K17: =J17 -> 179
B18: EBITDA | E18: =E10+E16+E17 -> 2726 | F18: =F10+F16+F17 -> 4560 | G18: =G10+G16+G17 -> 2883.9107 | H18: =H10+H16+H17 -> 3394.7938 | I18: =I10+I16+I17 -> 6568.3499 | J18: =J10+J16+J17 -> 7285.1537 | K18: =K10+K16+K17 -> 6445.6951
B19: EBITDA margin | E19: =E18/E10 -> 0.12289798 | F19: =F18/F10 -> 0.20521129 | G19: =G18/G10 -> 0.11833568 | H19: =H18/H10 -> 0.12762132 | I19: =I18/I10 -> 0.22731766 | J19: =J18/J10 -> 0.23323059 | K19: =K18/K10 -> 0.19089078
B21: Depreciation | G21: =-G378-G327 -> -2325.9157 | H21: =-H378-H327 -> -2737.562 | I21: =-I378-I327 -> -3190.8194 | J21: =-J378-J327 -> -3869.7993 | K21: =-K378-K327 -> -4984.9043
B22: Amortisation | G22: =-G415 -> -395.35487 | H22: =-H415 -> -414.46904 | I22: =-I415 -> -435.27987 | J22: =-J415 -> -457.82895 | K22: =-K415 -> -482.20479
B23: Depreciation and Amortisation | E23: -1839 | F23: -1942 | G23: =SUM(G21:G22) -> -2721.2706 | H23: =SUM(H21:H22) -> -3152.031 | I23: =SUM(I21:I22) -> -3626.0993 | J23: =SUM(J21:J22) -> -4327.6282 | K23: =SUM(K21:K22) -> -5467.1091
B25: EBIT | E25: =E18+E23 -> 887 | F25: =F18+F23 -> 2618 | G25: =G18+G23 -> 162.64012 | H25: =H18+H23 -> 242.76279 | I25: =I18+I23 -> 2942.2506 | J25: =J18+J23 -> 2957.5255 | K25: =K18+K23 -> 978.58604
B26: Operating profit margin | E26: =E25/E10 -> 0.03998918 | F26: =F25/F10 -> 0.11781648 | G26: =G25/G10 -> 0.006673622 | H26: =H25/H10 -> 0.0091262416 | I26: =I25/I10 -> 0.1018255 | J26: =J25/J10 -> 0.094683713 | K26: =K25/K10 -> 0.028981057
B28: Finance income | E28: 42 | F28: 117 | G28: =G520 -> 67.436579 | H28: =H520 -> 85.752818 | I28: =I520 -> 82.851666 | J28: =J520 -> 90.089176 | K28: =K520 -> 122.33822
B29: Finance costs - lease liabilities | E29: -940 | F29: -911 | G29: =G343 -> -827.63848 | H29: =H343 -> -767.72472 | I29: =I343 -> -763.92235 | J29: =J343 -> -708.69165 | K29: =K343 -> -820.20563
B30: Finance costs | E30: -541 | F30: -506 | G30: =-G514 -> -222.7536 | H30: =-H514 -> -222.7536 | I30: =-I514 -> -222.7536 | J30: =-J514 -> -222.7536 | K30: =-K514 -> -222.7536
B31: Net finance costs | E31: =SUM(E28:E30) -> -1439 | F31: =SUM(F28:F30) -> -1300 | G31: =SUM(G28:G30) -> -982.9555 | H31: =SUM(H28:H30) -> -904.7255 | I31: =SUM(I28:I30) -> -903.82429 | J31: =SUM(J28:J30) -> -841.35608 | K31: =SUM(K28:K30) -> -920.62101
B33: Depreciation on ROU asset - non operating aircraft | E33: -396 | F33: -419
B34: Finance costs - lease liabilities - non operating aircraft | E34: -245 | F34: -239
B35: Net foreign exchange gain/(loss) | E35: 279 | F35: 1370
B36: Share of results of associates | E36: 4 | F36: 26 | G36: =F36 -> 26 | H36: =G36 -> 26 | I36: =H36 -> 26 | J36: =I36 -> 26 | K36: =J36 -> 26
B37: Derivatives | E37: 5 | F37: -16 | G37: =F37 -> -16 | H37: =G37 -> -16 | I37: =H37 -> -16 | J37: =I37 -> -16 | K37: =J37 -> -16
B38: Profit before taxation | E38: =E25+E31+SUM(E33:E37) -> -905 | F38: =F25+F31+SUM(F33:F37) -> 2040 | G38: =G25+G31+SUM(G33:G37) -> -810.31538 | H38: =H25+H31+SUM(H33:H37) -> -651.96271 | I38: =I25+I31+SUM(I33:I37) -> 2048.4263 | J38: =J25+J31+SUM(J33:J37) -> 2126.1694 | K38: =K25+K31+SUM(K33:K37) -> 67.965021
B40: Taxation | E40: -109 | F40: -78 | G40: =-G549 -> 0 | H40: =-H549 -> 0 | I40: =-I549 -> -491.62232 | J40: =-J549 -> -510.28065 | K40: =-K549 -> -16.311605
B41: Net Profit | E41: =E38+SUM(E40:E40) -> -1014 | F41: =F38+SUM(F40:F40) -> 1962 | G41: =G38+SUM(G40:G40) -> -810.31538 | H41: =H38+SUM(H40:H40) -> -651.96271 | I41: =I38+SUM(I40:I40) -> 1556.804 | J41: =J38+SUM(J40:J40) -> 1615.8887 | K41: =K38+SUM(K40:K40) -> 51.653416
B42: Net Profit Margin | E42: =E41/E10 -> -0.045714801 | F42: =F41/F10 -> 0.088294856 | G42: =G41/G10 -> -0.03324972 | H42: =H41/H10 -> -0.024509395 | I42: =I41/I10 -> 0.053877922 | J42: =J41/J10 -> 0.051731877 | K42: =K41/K10 -> 0.0015297281
B44: Earning per share
B45: - Basic | C45: sen per share | G45: =G41*100000000/G600 -> -24.110599 | H45: =H41*100000000/H600 -> -19.398881 | I45: =I41*100000000/I600 -> 46.32206 | J45: =J41*100000000/J600 -> 48.080101 | K45: =K41*100000000/K600 -> 1.536926
B46: - Diluted | C46: sen per share | G46: =G41*100000000/G602 -> -24.110599 | H46: =H41*100000000/H602 -> -19.398881 | I46: =I41*100000000/I602 -> 46.32206 | J46: =J41*100000000/J602 -> 48.080101 | K46: =K41*100000000/K602 -> 1.536926
B49: Air Asia Group
B50: Financial Statements - Balance Sheet
B52: RM millions, unless otherwise stated
E54: 2024 | F54: 2025 | G54: =F54+1 -> 2026 | H54: =G54+1 -> 2027 | I54: =H54+1 -> 2028 | J54: =I54+1 -> 2029 | K54: =J54+1 -> 2030
...

Sheet Sheet1
B1: =Cover!$B$2 -> Air Asia
B2: Financial Statements - Balance Sheet Reconciliation
C5: Units / RM'000 | E5: 2026 Q1 | F5: 2025 PF | G5: Notes
B6: Income Statement Anchors
B8: Revenue | E8: 5950000 | F8: 22200000
B9: Annualized Revenue | E9: =4*E8 -> 23800000 | F9: =F8 -> 22200000
B11: Assets
B13: PP&E | E13: 1293133 | F13: =($F$9/$E$9)*E13 -> 1206199.7 | G13: Adjusted based on annualized revenue
B14: ROU assets | E14: 12012506 | F14: =($F$9/$E$9)*E14 -> 11204943 | G14: Adjusted based on annualized revenue
B15: Finance lease receivables | E15: 154490 | F15: =E15 -> 154490 | G15: Hold flat
B16: Investment in associates | E16: 449244 | F16: =E16 -> 449244 | G16: Held flat
B17: Investment securities | E17: 122 | F17: =E17 -> 122 | G17: Held flat - as immaterial
B18: Intangible assets | E18: 13953159 | F18: =E18 -> 13953159 | G18: Held flat - as goodwill tends to be impaired
B19: Deferred tax assets | E19: 1706569 | F19: =E19 -> 1706569 | G19: Held flat
B20: Receivables and prepayments | E20: 8070813 | F20: 5910344.7 | G20: Adjusted for the first pass to allow for reconciliation
B21: Deposits on aircraft purchases | E21: 607213 | F21: =E21 -> 607213 | G21: Have assumed no change
B22: Amount due from associates | E22: 27825 | F22: =E22 -> 27825 | G22: Held flat
B23: Derivatives | E23: 891 | F23: =E23 -> 891 | G23: Held flat
B24: Non-current assets | E24: =SUM(E13:E23) -> 38275965 | F24: =SUM(F13:F23) -> 35221000
B25: Non current assets - actuals | F25: 35221000
B27: Inventories | E27: 192124 | F27: =($F$9/$E$9)*E27 -> 179208.1 | G27: Adjusted based on annualized revenue
B28: Receivables and prepayments | E28: 1595895 | F28: =($F$9/$E$9)*E28 -> 1488607.9 | G28: Adjusted based on annualized revenue
B29: Finance lease receivables | E29: 27776 | F29: =E29 -> 27776 | G29: Held flat
B30: Amounts due from related parties | E30: 1262127 | F30: =E30 -> 1262127 | G30: Held flat
B31: Amount due from associates | E31: 174471 | F31: =E31 -> 174471 | G31: Held flat
B32: Derivatives | E32: 17159 | F32: =E32 -> 17159 | G32: Held flat
B33: Tax recoverable | E33: 16765 | F33: =E33 -> 16765 | G33: Held flat
B34: Cash | E34: 1085766 | F34: =F36-SUM(F27:F33) -> 2247886
B35: Total current assets | E35: =SUM(E27:E34) -> 4372083 | F35: =SUM(F27:F34) -> 5414000
B36: Current assets - actuals | F36: 5414000
B38: Total assets | E38: =E24+E35 -> 42648048 | F38: =F24+F35 -> 40635000
B39: Total assets - actuals | F39: =F25+F36 -> 40635000
B41: Liabilities
B43: Aircraft maintenance provision | E43: 6689552 | F43: 7193542.2 | G43: Manually adjusted for first pass
B44: Borrowings | E44: 2537062 | F44: =E44 -> 2537062
B45: Long-term debentures | E45: 930421 | F45: =E45 -> 930421
B46: Lease liabilities | E46: 12338502 | F46: 12651278 | G46: Manually adjusted for first pass
B47: Deferred tax liabilities | E47: 739697 | F47: =E47 -> 739697
B48: Non-current liabilities | E48: =SUM(E43:E47) -> 23235234 | F48: =SUM(F43:F47) -> 24052000
B49: Non-current liabilities - actuals | F49: 24052000
...
