Workbook

Sheet Cover
B2: Greggs
B4: Modelled by Peter Hopkinson
B5: =DATE(2026, 10, 11) -> 46306

Sheet DCF_Valuation
B2: =Cover!$B$2 -> Greggs
B3: Discounted Cash Flow - FCFF and Equity Bridge
F5: Fiscal Years Ending December 31
F6: 2024 | G6: 2025 | H6: =G6+1 -> 2026 | I6: =H6+1 -> 2027 | J6: =I6+1 -> 2028 | K6: =J6+1 -> 2029 | L6: =K6+1 -> 2030
B7: (£m in millions) | F7: H = Historical | L7: F = Forecast
B9: Unlevered Free Cash Flow
B11: EBIT | H11: =Model!H18 -> 244.63268 | I11: =Model!I18 -> 259.07778 | J11: =Model!J18 -> 282.71945 | K11: =Model!K18 -> 315.41621 | L11: =Model!L18 -> 360.24654
B12: Tax Rate | H12: =Model!H489 -> 0.26 | I12: =Model!I489 -> 0.26 | J12: =Model!J489 -> 0.26 | K12: =Model!K489 -> 0.26 | L12: =Model!L489 -> 0.26
B13: NOPAT | H13: =H11*(1-H12) -> 181.02818 | I13: =I11*(1-I12) -> 191.71755 | J13: =J11*(1-J12) -> 209.21239 | K13: =K11*(1-K12) -> 233.40799 | L13: =L11*(1-L12) -> 266.58244
B14: (+) D&A | H14: =-Model!H24 -> 147.10816 | I14: =-Model!I24 -> 174.57844 | J14: =-Model!J24 -> 200.81556 | K14: =-Model!K24 -> 226.16294 | L14: =-Model!L24 -> 251.80238
B15: (-) Capital expenditure | H15: =-Model!H115 -> 203.05822 | I15: =-Model!I115 -> 192.77425 | J15: =-Model!J115 -> 179.1654 | K15: =-Model!K115 -> 176.3646 | L15: =-Model!L115 -> 187.03805
B16: (+) Change in NWC | H16: =Model!H286 -> 6.5086943 | I16: =Model!I286 -> 11.425813 | J16: =Model!J286 -> 10.422619 | K16: =Model!K286 -> 9.4733296 | L16: =Model!L286 -> 8.3877543
B17: FCFF* | H17: =H13+H14-H15+H16 -> 131.58682 | I17: =I13+I14-I15+I16 -> 184.94756 | J17: =J13+J14-J15+J16 -> 241.28517 | K17: =K13+K14-K15+K16 -> 292.67965 | L17: =L13+L14-L15+L16 -> 339.73452
B19: Discounted Cash Flow
B20: Discount period | H20: 1 | I20: =H20+1 -> 2 | J20: =I20+1 -> 3 | K20: =J20+1 -> 4 | L20: =K20+1 -> 5
B21: PV of FCFF | H21: =H17/(1+$D$33)^H20 -> 121.57046 | I21: =I17/(1+$D$33)^I20 -> 157.86283 | J21: =J17/(1+$D$33)^J20 -> 190.27317 | K21: =K17/(1+$D$33)^K20 -> 213.23334 | L21: =L17/(1+$D$33)^L20 -> 228.67459
B23: WACC | F23: Terminal Assumptions
B25: Risk-free rate | D25: 0.05527 | F25: Terminal Growth | H25: 0.02
B26: Equity-risk premium | D26: =D77 -> 0.0498 | F26: Final Forecast Year | H26: =L6 -> 2030
B27: Beta | D27: =D71 -> 0.715331 | F27: Valuation Method | H27: Gordon Growth
B28: Cost of Equity | D28: =D25+D26*D27 -> 0.090893484 | F28: Shares outstanding | H28: =Model!D41 -> 102250000
B29: Cost of Debt | D29: 0.059
B30: Tax Rate | D30: 0.26
B31: Equity weight | D31: 0.82
B32: Debt weight | D32: 0.18
B33: WACC | D33: =D28*D31+D32*D29*(1-D30) -> 0.082391457
B36: Valuation Output
B38: PV of forecast FCFF | D38: =SUM(H21:L21) -> 911.61439
B39: Terminal Value | D39: =(L17*(1+H25))/(D33+H25) -> 3384.3567
B40: Enterprise Value | D40: =SUM(D38:D39) -> 4295.9711
B42: (+) Cash | D42: =Model!G56 -> 70.8
B43: (-) Financial Debt | D43: =-Model!G74 -> 25
B44: (-) Lease liabilities | D44: =-Model!G77-Model!G70 -> 449.8
B45: Equity Value | D45: =D40+D42-D43-D44 -> 3891.9711
B46: Implied share price | D46: =D45/H28 * 1000000 -> 38.063287
B49: =Cover!$B$2 -> Greggs
B50: Discounted Cash Flow - WACC Components
B52: (£m in millions)
B54: Comparable Company Beta
B56: Company | D56: Ticker | E56: Levered ϐ | F56: Market Cap | G56: Debt | H56: D/E | I56: Tax | J56: Unlevered ϐ | K56: Observation Date
...

Sheet Assumptions
B2: =Cover!$B$2 -> Greggs
B3: Assumptions | L3: ="Currently Running: "&CHOOSE(Assumptions!$B$10,Assumptions!$F$15,Assumptions!$F$16,Assumptions!$F$17)&"Scenario" -> Currently Running: Base Scenario
F5: Fiscal Years Ending December 31
F6: 2024 | G6: 2025 | H6: =G6+1 -> 2026 | I6: =H6+1 -> 2027 | J6: =I6+1 -> 2028 | K6: =J6+1 -> 2029 | L6: =K6+1 -> 2030
B7: (£m in millions) | F7: H = Historical | L7: F = Forecast
B9: Scenario Selector:
B10: 1
B12: Macro Assumptions
B14: Wage Inflation | F14: Selected | H14: =CHOOSE($B$10,H15,H16,H17) -> 0.04 | I14: =CHOOSE($B$10,I15,I16,I17) -> 0.04 | J14: =CHOOSE($B$10,J15,J16,J17) -> 0.035 | K14: =CHOOSE($B$10,K15,K16,K17) -> 0.03 | L14: =CHOOSE($B$10,L15,L16,L17) -> 0.025
F15: Base | H15: 0.04 | I15: 0.04 | J15: 0.035 | K15: 0.03 | L15: 0.025
F16: Upside | H16: 0.0375 | I16: 0.03 | J16: 0.025 | K16: 0.02 | L16: 0.02
F17: Downside | H17: 0.045 | I17: 0.05 | J17: 0.0475 | K17: 0.04 | L17: 0.035
B19: Food Cost Inflation | F19: Selected | H19: =CHOOSE($B$10,H20,H21,H22) -> 0.04 | I19: =CHOOSE($B$10,I20,I21,I22) -> 0.04 | J19: =CHOOSE($B$10,J20,J21,J22) -> 0.035 | K19: =CHOOSE($B$10,K20,K21,K22) -> 0.03 | L19: =CHOOSE($B$10,L20,L21,L22) -> 0.025
F20: Base | H20: 0.04 | I20: 0.04 | J20: 0.035 | K20: 0.03 | L20: 0.025
F21: Upside | H21: 0.0375 | I21: 0.03 | J21: 0.025 | K21: 0.02 | L21: 0.02
F22: Downside | H22: 0.045 | I22: 0.05 | J22: 0.0475 | K22: 0.04 | L22: 0.035
B24: Inflation | F24: Selected | H24: =CHOOSE($B$10,H25,H26,H27) -> 0.04 | I24: =CHOOSE($B$10,I25,I26,I27) -> 0.04 | J24: =CHOOSE($B$10,J25,J26,J27) -> 0.035 | K24: =CHOOSE($B$10,K25,K26,K27) -> 0.03 | L24: =CHOOSE($B$10,L25,L26,L27) -> 0.025
F25: Base | H25: 0.04 | I25: 0.04 | J25: 0.035 | K25: 0.03 | L25: 0.025
F26: Upside | H26: 0.0375 | I26: 0.03 | J26: 0.025 | K26: 0.02 | L26: 0.02
F27: Downside | H27: 0.045 | I27: 0.05 | J27: 0.0475 | K27: 0.04 | L27: 0.035
B30: Revenue Assumptions
B33: Like-for-like sales growth rate - own stores | F33: Selected | H33: =CHOOSE($B$10,H34,H35,H36) -> 0.035 | I33: =CHOOSE($B$10,I34,I35,I36) -> 0.035 | J33: =CHOOSE($B$10,J34,J35,J36) -> 0.035 | K33: =CHOOSE($B$10,K34,K35,K36) -> 0.035 | L33: =CHOOSE($B$10,L34,L35,L36) -> 0.035
F34: Base | H34: 0.035 | I34: 0.035 | J34: 0.035 | K34: 0.035 | L34: 0.035
F35: Upside | H35: 0.05 | I35: 0.05 | J35: 0.05 | K35: 0.05 | L35: 0.05
F36: Downside | H36: 0 | I36: 0.005 | J36: 0.015 | K36: 0.02 | L36: 0.02
B38: Like-for-like sales growth rate - franchise stores | F38: Selected | H38: =CHOOSE($B$10,H39,H40,H41) -> 0.06 | I38: =CHOOSE($B$10,I39,I40,I41) -> 0.05 | J38: =CHOOSE($B$10,J39,J40,J41) -> 0.045 | K38: =CHOOSE($B$10,K39,K40,K41) -> 0.04 | L38: =CHOOSE($B$10,L39,L40,L41) -> 0.04
F39: Base | H39: 0.06 | I39: 0.05 | J39: 0.045 | K39: 0.04 | L39: 0.04
F40: Upside | H40: 0.09 | I40: 0.08 | J40: 0.065 | K40: 0.06 | L40: 0.05
F41: Downside | H41: 0.005 | I41: 0.005 | J41: 0.01 | K41: 0.015 | L41: 0.02

Sheet Model
B3: =Cover!$B$2 -> Greggs
B4: Financial Statements - Income Statement | L4: ="Currently Running: "&CHOOSE(Assumptions!$B$10,Assumptions!$F$15,Assumptions!$F$16,Assumptions!$F$17)&"Scenario" -> Currently Running: Base Scenario
F6: Fiscal Years Ending December 31
F7: 2024 | G7: 2025 | H7: =G7+1 -> 2026 | I7: =H7+1 -> 2027 | J7: =I7+1 -> 2028 | K7: =J7+1 -> 2029 | L7: =K7+1 -> 2030
B8: (£m in millions) | F8: H = Historical | L8: F = Forecast
B10: Revenue | F10: 2014.4 | G10: 2151.2 | H10: =H217 -> 2320.6653 | I10: =I217 -> 2487.4096 | J10: =J217 -> 2654.3023 | K10: =K217 -> 2821.8337 | L10: =L217 -> 2992.6089
B11: Cost of Sales | F11: -770.8 | G11: -829.1 | H11: =-H264 -> -874.83541 | I11: =-I264 -> -939.01394 | J11: =-J264 -> -999.37957 | K11: =-K264 -> -1056.1986 | L11: =-L264 -> -1109.2715
B12: Gross profit | F12: =SUM(F10:F11) -> 1243.6 | G12: =SUM(G10:G11) -> 1322.1 | H12: =SUM(H10:H11) -> 1445.8299 | I12: =SUM(I10:I11) -> 1548.3957 | J12: =SUM(J10:J11) -> 1654.9227 | K12: =SUM(K10:K11) -> 1765.6351 | L12: =SUM(L10:L11) -> 1883.3374
B13: Gross profit margin | F13: =F12/F10 -> 0.61735504 | G13: =G12/G10 -> 0.61458721 | H13: =H12/H10 -> 0.62302388 | I13: =I12/I10 -> 0.62249324 | J13: =J12/J10 -> 0.6234869 | K13: =K12/K10 -> 0.62570487 | L13: =L12/L10 -> 0.62932962
B15: Distribution and selling costs | F15: -950.1 | G15: -1036.3 | H15: =-H265 -> -1093.4651 | I15: =-I265 -> -1173.6825 | J15: =-J265 -> -1249.1341 | K15: =-K265 -> -1320.1527 | L15: =-L265 -> -1386.489
B16: Administrative expenses | F16: -97.9 | G16: -102.1 | H16: =-H266 -> -107.73211 | I16: =-I266 -> -115.63542 | J16: =-J266 -> -123.06918 | K16: =-K266 -> -130.06619 | L16: =-L266 -> -136.60188
B17: Other income | F17: 13.8 | G17: 0 | H17: =G17 -> 0 | I17: =H17 -> 0 | J17: =I17 -> 0 | K17: =J17 -> 0 | L17: =K17 -> 0
B18: EBIT | F18: =SUM(F15:F17)+F12 -> 209.4 | G18: =SUM(G15:G17)+G12 -> 183.7 | H18: =SUM(H15:H17)+H12 -> 244.63268 | I18: =SUM(I15:I17)+I12 -> 259.07778 | J18: =SUM(J15:J17)+J12 -> 282.71945 | K18: =SUM(K15:K17)+K12 -> 315.41621 | L18: =SUM(L15:L17)+L12 -> 360.24654
B19: EBIT Margin | F19: =F18/F10 -> 0.10395155 | G19: =G18/G10 -> 0.085394199 | H19: =H18/H10 -> 0.10541489 | I19: =I18/I10 -> 0.10415565 | J19: =J18/J10 -> 0.10651366 | K19: =K18/K10 -> 0.11177704 | L19: =L18/L10 -> 0.12037876
B21: Depreciation of PP&E | F21: =-F385 -> -76.6 | G21: =-G385 -> -90.7 | H21: =-H385 -> -92.492661 | I21: =-I385 -> -110.48126 | J21: =-J385 -> -127.1501 | K21: =-K385 -> -142.87305 | L21: =-L385 -> -158.86276
B22: Depreciation of ROU assets | F22: =-F331/1000000 -> -59.2 | G22: =-G331/1000000 -> -65.2 | H22: =-H331/1000000 -> -44.275 | I22: =-I331/1000000 -> -50.150625 | J22: =-J331/1000000 -> -55.862625 | K22: =-K331/1000000 -> -61.379948 | L22: =-L331/1000000 -> -66.668848
B23: Amortisation | F23: =-F407 -> -4.2 | G23: =-G407 -> -4.7 | H23: =-H407 -> -10.340499 | I23: =-I407 -> -13.946555 | J23: =-J407 -> -17.802839 | K23: =-K407 -> -21.909941 | L23: =-L407 -> -26.270773
B24: Depreciation and Amortization | F24: =SUM(F21:F23) -> -140 | G24: =SUM(G21:G23) -> -160.6 | H24: =SUM(H21:H23) -> -147.10816 | I24: =SUM(I21:I23) -> -174.57844 | J24: =SUM(J21:J23) -> -200.81556 | K24: =SUM(K21:K23) -> -226.16294 | L24: =SUM(L21:L23) -> -251.80238
B25: EBITDA | F25: =F18-F24 -> 349.4 | G25: =G18-G24 -> 344.3 | H25: =H18-H24 -> 391.74084 | I25: =I18-I24 -> 433.65621 | J25: =J18-J24 -> 483.53501 | K25: =K18-K24 -> 541.57914 | L25: =L18-L24 -> 612.04892
B26: EBITDA Margin | F26: =F25/F10 -> 0.17345115 | G26: =G25/G10 -> 0.1600502 | H26: =H25/H10 -> 0.1688054 | I26: =I25/I10 -> 0.17434049 | J26: =J25/J10 -> 0.18217029 | K26: =K25/K10 -> 0.19192454 | L26: =L25/L10 -> 0.20452019
B28: Finance income | F28: 8.1 | G28: 1.8 | H28: =H466 -> 0.708 | I28: =I466 -> 0.47724928 | J28: =J466 -> 1.0000971 | K28: =K466 -> 2.0292823 | L28: =L466 -> 3.4939014
B29: Finance expense | F29: -13.6 | G29: -18.1 | H29: =-H460+H350 -> -28.338 | I29: =-I460+I350 -> -27.37728 | J29: =-J460+J350 -> -27.700667 | K29: =-K460+K350 -> -27.936357 | L29: =-L460+L350 -> -28.059676
B30: Net finance costs | F30: =SUM(F28:F29) -> -5.5 | G30: =SUM(G28:G29) -> -16.3 | H30: =SUM(H28:H29) -> -27.63 | I30: =SUM(I28:I29) -> -26.900031 | J30: =SUM(J28:J29) -> -26.70057 | K30: =SUM(K28:K29) -> -25.907074 | L30: =SUM(L28:L29) -> -24.565775
B32: Profit before tax | F32: =F18+F30 -> 203.9 | G32: =G18+G30 -> 167.4 | H32: =H18+H30 -> 217.00268 | I32: =I18+I30 -> 232.17775 | J32: =J18+J30 -> 256.01888 | K32: =K18+K30 -> 289.50913 | L32: =L18+L30 -> 335.68076
B34: Taxation | F34: -50.5 | G34: -46.1 | H34: =-H502 -> -56.420697 | I34: =-I502 -> -60.366214 | J34: =-J502 -> -66.564909 | K34: =-K502 -> -75.272374 | L34: =-L502 -> -87.276998
B35: Net Profit | F35: =F32+F34 -> 153.4 | G35: =G32+G34 -> 121.3 | H35: =H32+H34 -> 160.58198 | I35: =I32+I34 -> 171.81153 | J35: =J32+J34 -> 189.45397 | K35: =K32+K34 -> 214.23676 | L35: =L32+L34 -> 248.40376
B36: Net Profit Margin | F36: =F35/F10 -> 0.076151708 | G36: =G35/G10 -> 0.056387133 | H36: =H35/H10 -> 0.069196528 | I36: =I35/I10 -> 0.069072472 | J36: =J35/J10 -> 0.071376186 | K36: =K35/K10 -> 0.075921114 | L36: =L35/L10 -> 0.083005757
B38: Earning per share
B39: - Basic | D39: pence per share | H39: =(H35*1000000/$D$41)*100 -> 157.0484 | I39: =(I35*1000000/$D$41)*100 -> 168.03084 | J39: =(J35*1000000/$D$41)*100 -> 185.28506 | K39: =(K35*1000000/$D$41)*100 -> 209.5225 | L39: =(L35*1000000/$D$41)*100 -> 242.93767
B41: Shares Trading | D41: 102250000
B45: =Cover!$B$2 -> Greggs
B46: Financial Statements - Balance Sheet | L46: ="Currently Running: "&CHOOSE(Assumptions!$B$10,Assumptions!$F$15,Assumptions!$F$16,Assumptions!$F$17)&"Scenario" -> Currently Running: Base Scenario
F48: Fiscal Years Ending December 31
F49: 2024 | G49: 2025 | H49: =G49+1 -> 2026 | I49: =H49+1 -> 2027 | J49: =I49+1 -> 2028 | K49: =J49+1 -> 2029 | L49: =K49+1 -> 2030
B50: (£m in millions) | F50: H = Historical | L50: F = Forecast
B52: Assets
B54: Inventories | F54: 55.2 | G54: 55.7 | H54: =H281 -> 58.772563 | I54: =I281 -> 63.084159 | J54: =J281 -> 67.1396 | K54: =K281 -> 70.956774 | L54: =L281 -> 74.522278
B55: Trade and other receivables | F55: 62.4 | G55: 69.4 | H55: =H280 -> 74.867132 | I55: =I280 -> 80.24648 | J55: =J280 -> 85.630614 | K55: =K280 -> 91.035356 | L55: =L280 -> 96.544745
B56: Cash and cash equivalents | F56: 125.3 | G56: 70.8 | H56: =H129 -> 47.724928 | I56: =I129 -> 100.00971 | J56: =J129 -> 202.92823 | K56: =K129 -> 349.39014 | L56: =L129 -> 532.06435
B57: Current Assets | F57: =SUM(F54:F56) -> 242.9 | G57: =SUM(G54:G56) -> 195.9 | H57: =SUM(H54:H56) -> 181.36462 | I57: =SUM(I54:I56) -> 243.34035 | J57: =SUM(J54:J56) -> 355.69845 | K57: =SUM(K54:K56) -> 511.38227 | L57: =SUM(L54:L56) -> 703.13137
...
