Workbook

Sheet Cover
B2: OSB
B4: Modelled by Peter Hopkinson
B5: =DATE(2026, 9, 29) -> 46294

Sheet Assumptions
B2: =Cover!$B$2 -> OSB
B3: Model Assumptions
C5: Units | D5: 2026 | E5: =D5+1 -> 2027 | F5: =E5+1 -> 2028 | G5: =F5+1 -> 2029 | H5: =G5+1 -> 2030
B6: Macro Assumptions
B8: Bank Rate | C8: % | D8: 0.0375 | E8: 0.045 | F8: 0.035 | G8: 0.03 | H8: 0.025
B9: SONIA | C9: % | D9: 0.039 | E9: 0.0465 | F9: 0.0365 | G9: 0.0315 | H9: 0.0265
B10: Inflation | C10: % | D10: 0.0325 | E10: 0.035 | F10: 0.0275 | G10: 0.025 | H10: 0.025
B12: Loan Book Assumptions - OSB
B14: BTL origination growth rate | C14: % | D14: -0.02 | E14: -0.02 | F14: -0.02 | G14: -0.02 | H14: 0
B15: BTL redemption rate | C15: % | D15: 0.09 | E15: 0.09 | F15: 0.09 | G15: 0.09 | H15: 0.09
B16: Residential origination growth rate | C16: % | D16: -0.5 | E16: -0.5
B17: Residential redemption rate | C17: % | D17: 0.175 | E17: 0.175 | F17: 0.175 | G17: 0.175 | H17: 0.175
B18: Residential development origination growth rate | C18: % | D18: 0.2 | E18: 0.15 | F18: 0.12 | G18: 0.08 | H18: 0.06
B19: Residential development redemption rate | C19: % | D19: 0.75 | E19: 0.75 | F19: 0.75 | G19: 0.75 | H19: 0.75
B20: Commercial origination growth rate | C20: % | D20: 0.1 | E20: 0.1 | F20: 0.08 | G20: 0.06 | H20: 0.06
B21: Commercial redemption rate | C21: % | D21: 0.15 | E21: 0.15 | F21: 0.17 | G21: 0.19 | H21: 0.2
B22: Asset Finance origination growth rate | C22: % | D22: 0.25 | E22: 0.2 | F22: 0.15 | G22: 0.12 | H22: 0.1
B23: Asset Finance redemption rate | C23: % | D23: 0.33 | E23: 0.33 | F23: 0.33 | G23: 0.33 | H23: 0.33
B25: Loan Book Assumptions - CCFS
B27: BTL origination growth rate | C27: % | D27: 0 | E27: 0 | F27: 0 | G27: 0 | H27: 0
B28: BTL redemption rate | C28: % | D28: 0.08 | E28: 0.08 | F28: 0.08 | G28: 0.08 | H28: 0.08
B29: Residential origination growth rate | C29: % | D29: 0.1 | E29: 0.1 | F29: 0.1 | G29: 0.1 | H29: 0.1
B30: Residential redemption rate | C30: % | D30: 0.175 | E30: 0.175 | F30: 0.175 | G30: 0.175 | H30: 0.175
B32: Asset Spreads over SONIA
B34: One savings bank
B36: BTL spread | C36: % | D36: 0.0225 | E36: 0.0225 | F36: 0.0225 | G36: 0.0225 | H36: 0.0225
B37: Residential spread | C37: % | D37: 0.02 | E37: 0.02 | F37: 0.02 | G37: 0.02 | H37: 0.02
B38: Residential development spread | C38: % | D38: 0.06 | E38: 0.06 | F38: 0.06 | G38: 0.06 | H38: 0.06
B39: Commercial spread | C39: % | D39: 0.04 | E39: 0.04 | F39: 0.04 | G39: 0.04 | H39: 0.04
B40: Asset Finance spread | C40: % | D40: 0.045 | E40: 0.045 | F40: 0.045 | G40: 0.045 | H40: 0.045
B42: CCFS
B44: BTL spread | C44: % | D44: 0.0225 | E44: 0.0225 | F44: 0.0225 | G44: 0.0225 | H44: 0.0225
B45: Residential spread | C45: % | D45: 0.025 | E45: 0.025 | F45: 0.025 | G45: 0.025 | H45: 0.025
B47: Funding assumptions
B49: Deposit growth rate | C49: % | D49: 0.02 | E49: 0.02 | F49: 0.02 | G49: 0.02 | H49: 0.02
B50: Retail deposit spread | C50: % | D50: 0 | E50: 0 | F50: 0 | G50: 0 | H50: 0
B51: Retail deposit cost | C51: % | D51: =D9+D50 -> 0.039 | E51: =E9+E50 -> 0.0465 | F51: =F9+F50 -> 0.0365 | G51: =G9+G50 -> 0.0315 | H51: =H9+H50 -> 0.0265
B53: Securitisation redemption | C53: % | D53: 0.2 | E53: 0.2 | F53: 0.2 | G53: 0.2 | H53: 0.2
B54: Securitisation spread | C54: % | D54: 0.01 | E54: 0.01 | F54: 0.01 | G54: 0.01 | H54: 0.01
B55: Securitisation issuance | C55: £m | D55: 0 | E55: 0 | F55: 0 | G55: 0 | H55: 0
...

Sheet Model
B2: =Cover!$B$2 -> OSB
B3: Financial Statements - Income Statement
C7: Units / £m | E7: 2024 | F7: 2025 | G7: =F7+1 -> 2026 | H7: =G7+1 -> 2027 | I7: =H7+1 -> 2028 | J7: =I7+1 -> 2029 | K7: =J7+1 -> 2030
B9: Interest Receivable | E9: 2099.3 | F9: 1914.8 | G9: =G299 -> 1891.2295 | H9: =H299 -> 2178.4571 | I9: =I299 -> 1910.3192 | J9: =J299 -> 1791.181 | K9: =K299 -> 1668.2097
B10: Interest Payable | E10: -1432.9 | F10: -1235.4 | G10: =-G337 -> -1188.3567 | H10: =-H337 -> -1411.0323 | I10: =-I337 -> -1141.4169 | J10: =-J337 -> -1011.3138 | K10: =-K337 -> -879.94391
B11: Net Interest Income | E11: =SUM(E9:E10) -> 666.4 | F11: =SUM(F9:F10) -> 679.4 | G11: =SUM(G9:G10) -> 702.87283 | H11: =SUM(H9:H10) -> 767.42471 | I11: =SUM(I9:I10) -> 768.90234 | J11: =SUM(J9:J10) -> 779.86723 | K11: =SUM(K9:K10) -> 788.26577
B13: Fair value losses on financial instruments | E13: -1.5 | F13: -22.1 | G13: =G476 -> 0 | H13: =H476 -> 0 | I13: =I476 -> 0 | J13: =J476 -> 0 | K13: =K476 -> 0
B14: Gain/(loss) on sale of financial assets | E14: -2.4 | F14: 3.4 | G14: =G477 -> 0 | H14: =H477 -> 0 | I14: =I477 -> 0 | J14: =J477 -> 0 | K14: =K477 -> 0
B15: Other operating income | E15: 4.7 | F15: 7.3 | G15: =G478 -> 7.3 | H15: =H478 -> 7.3 | I15: =I478 -> 7.3 | J15: =J478 -> 7.3 | K15: =K478 -> 7.3
B16: Total Income | E16: =SUM(E13:E15)+E11 -> 667.2 | F16: =SUM(F13:F15)+F11 -> 668 | G16: =SUM(G13:G15)+G11 -> 710.17283 | H16: =SUM(H13:H15)+H11 -> 774.72471 | I16: =SUM(I13:I15)+I11 -> 776.20234 | J16: =SUM(J13:J15)+J11 -> 787.16723 | K16: =SUM(K13:K15)+K11 -> 795.56577
B17: Administrative expenses | E17: -258.1 | F17: -270.1 | G17: =-G491 -> -281.70585 | H17: =-H491 -> -296.02401 | I17: =-I491 -> -309.94536 | J17: =-J491 -> -323.98766 | K17: =-K491 -> -338.43773
B18: Provisions for credit losses | E18: -2.7 | F18: -2.4 | G18: =0 -> 0 | H18: =0 -> 0 | I18: =0 -> 0 | J18: =0 -> 0 | K18: =0 -> 0
B19: Impairment of financial assets | E19: 11.7 | F19: -13 | G19: =-G419 -> -29.383707 | H19: =-H419 -> -31.525842 | I19: =-I419 -> -33.479301 | J19: =-J419 -> -35.168603 | K19: =-K419 -> -36.635799
B20: Profit before taxation | E20: =SUM(E16:E19) -> 418.1 | F20: =SUM(F16:F19) -> 382.5 | G20: =SUM(G16:G19) -> 399.08327 | H20: =SUM(H16:H19) -> 447.17486 | I20: =SUM(I16:I19) -> 432.77768 | J20: =SUM(J16:J19) -> 428.01096 | K20: =SUM(K16:K19) -> 420.49224
B21: Taxation | E21: -110 | F21: -96.8 | G21: =-G20*Assumptions!D106 -> -99.770817 | H21: =-H20*Assumptions!E106 -> -111.79372 | I21: =-I20*Assumptions!F106 -> -108.19442 | J21: =-J20*Assumptions!G106 -> -107.00274 | K21: =-K20*Assumptions!H106 -> -105.12306
B22: Profit for the year | E22: =SUM(E20:E21) -> 308.1 | F22: =SUM(F20:F21) -> 285.7 | G22: =SUM(G20:G21) -> 299.31245 | H22: =SUM(H20:H21) -> 335.38115 | I22: =SUM(I20:I21) -> 324.58326 | J22: =SUM(J20:J21) -> 321.00822 | K22: =SUM(K20:K21) -> 315.36918
B23: Other comprehensive expense | E23: -0.1 | F23: -0.7 | G23: 0 | H23: 0 | I23: 0 | J23: 0 | K23: 0
B24: Total comprehensive income | E24: =SUM(E22:E23) -> 308 | F24: =SUM(F22:F23) -> 285 | G24: =SUM(G22:G23) -> 299.31245 | H24: =SUM(H22:H23) -> 335.38115 | I24: =SUM(I22:I23) -> 324.58326 | J24: =SUM(J22:J23) -> 321.00822 | K24: =SUM(K22:K23) -> 315.36918
B26: Earning per share | C26: Units
B27: - Basic | C27: pence per share
B28: - Diluted | C28: pence per share
B31: =Cover!$B$2 -> OSB
B32: Financial Statements - Balance Sheet
C36: Units / £m | E36: 2024 | F36: 2025 | G36: =F36+1 -> 2026 | H36: =G36+1 -> 2027 | I36: =H36+1 -> 2028 | J36: =I36+1 -> 2029 | K36: =J36+1 -> 2030
B37: Assets
B38: Cash and cash equivalents | E38: 3406.2 | F38: 3053.4 | G38: =G75-SUM(G39:G48) -> 2336.9875 | H38: =H75-SUM(H39:H48) -> 1755.2055 | I38: =I75-SUM(I39:I48) -> 1310.8738 | J38: =J75-SUM(J39:J48) -> 1099.7678 | K38: =K75-SUM(K39:K48) -> 1006.626
B39: Investment securities | E39: 1434.4 | F39: 1814.5 | G39: =F39 -> 1814.5 | H39: =G39 -> 1814.5 | I39: =H39 -> 1814.5 | J39: =I39 -> 1814.5 | K39: =J39 -> 1814.5
B40: Loans and advances to customers | E40: 25126.3 | F40: 25920.6 | G40: =G193 -> 26875.02 | H40: =H193 -> 27824.606 | I40: =I193 -> 28627.273 | J40: =J193 -> 29290.54 | K40: =K193 -> 29893.119
B41: Fair value adjustments on hedged assets | E41: -179.3 | F41: 85.1 | G41: =F41 -> 85.1 | H41: =G41 -> 85.1 | I41: =H41 -> 85.1 | J41: =I41 -> 85.1 | K41: =J41 -> 85.1
B42: Derivative assets | E42: 313.8 | F42: 101.4 | G42: =F42 -> 101.4 | H42: =G42 -> 101.4 | I42: =H42 -> 101.4 | J42: =I42 -> 101.4 | K42: =J42 -> 101.4
B43: Other assets | E43: 17.8 | F43: 21 | G43: =F43 -> 21 | H43: =G43 -> 21 | I43: =H43 -> 21 | J43: =I43 -> 21 | K43: =J43 -> 21
B44: Current taxation asset | E44: 14.8 | F44: 1.7 | G44: =F44 -> 1.7 | H44: =G44 -> 1.7 | I44: =H44 -> 1.7 | J44: =I44 -> 1.7 | K44: =J44 -> 1.7
B45: Deferred taxation assets | E45: 6.2 | F45: 8.8 | G45: =F45 -> 8.8 | H45: =G45 -> 8.8 | I45: =H45 -> 8.8 | J45: =I45 -> 8.8 | K45: =J45 -> 8.8
B46: Non-current assets held for sale | E46: 0 | F46: 1.5 | G46: =F46 -> 1.5 | H46: =G46 -> 1.5 | I46: =H46 -> 1.5 | J46: =I46 -> 1.5 | K46: =J46 -> 1.5
B47: Property, plant and equipment | E47: 54.6 | F47: 47.8 | G47: =G457 -> 52.448571 | H47: =H457 -> 55.675743 | I47: =I457 -> 57.438872 | J47: =J457 -> 57.694038 | K47: =K457 -> 56.396002
B48: Intangible assets | E48: 48.8 | F48: 66.9 | G48: =G464 -> 83.453357 | H48: =H464 -> 96.773029 | I48: =I464 -> 106.76201 | J48: =J464 -> 113.32037 | K48: =K464 -> 116.34519
B49: Total assets | E49: =SUM(E38:E48) -> 30243.6 | F49: =SUM(F38:F48) -> 31122.7 | G49: =SUM(G38:G48) -> 31381.909 | H49: =SUM(H38:H48) -> 31766.261 | I49: =SUM(I38:I48) -> 32136.347 | J49: =SUM(J38:J48) -> 32595.322 | K49: =SUM(K38:K48) -> 33106.487
B52: Liabilities
B53: Amounts owed to credit institutions | E53: 1935.2 | F53: 1838.1 | G53: =G247 -> 1838.1 | H53: =H247 -> 1838.1 | I53: =I247 -> 1838.1 | J53: =J247 -> 1838.1 | K53: =K247 -> 1838.1
B54: Amounts owed to retail depositors | E54: 23820.3 | F54: 24251.1 | G54: =G210 -> 24736.122 | H54: =H210 -> 25230.844 | I54: =I210 -> 25735.461 | J54: =J210 -> 26250.171 | K54: =K210 -> 26775.174
...
