Workbook

Sheet Cover
B2: Paragon Bank
B4: Modelled by Peter Hopkinson
B5: =DATE(2026, 9, 25) -> 46290

Sheet Assumptions
B2: =Cover!$B$2 -> Paragon Bank
B3: Model Assumptions
C5: Units | D5: 2026 | E5: =D5+1 -> 2027 | F5: =E5+1 -> 2028 | H5: Notes
B6: Macro Assumptions
B8: Bank Rate | C8: % | D8: 0.0375 | E8: 0.045 | F8: 0.04
B9: SONIA | C9: % | D9: 0.0413 | E9: 0.0477 | F9: 0.0425
B10: Inflation | C10: % | D10: 0.0375 | E10: 0.035 | F10: 0.025
B12: Loan Book
B14: Mortgage Lending - Origination Rate | C14: % | D14: 0.05 | E14: 0.05 | F14: 0.05
B15: Commercial Lending - Origination Rates | C15: % | D15: 0.075 | E15: 0.075 | F15: 0.075
B16: Mortgage Lending - Redemption Rate | C16: % | D16: 0.08 | E16: 0.08 | F16: 0.08
B17: Commercial Lending - Redemption Rate | C17: % | D17: 0.45 | E17: 0.45 | F17: 0.45
B19: Funding Assumptions
B21: Deposit Growth Rates | C21: % | D21: 0.01 | E21: 0.01 | F21: 0.03
B22: Covered Bond Issuance | C22: £m | D22: 500 | E22: 0 | F22: 500
B23: Covered Bond Repayment | C23: £m | D23: 0 | E23: 0 | F23: 499.2
B24: Corporate Bond Issuance | C24: £m | D24: 200 | E24: 0 | F24: 0
B25: Corporate Bond Repayment | C25: £m | D25: 150.1 | E25: 0 | F25: 0
B26: TFSME Issuance / (Repayment) | C26: £m | D26: -250 | E26: 0 | F26: 0 | H26: * Remaining balance paid down as scheme ends
B27: ILTR Issuance / (Repayment) | C27: £m | D27: 1000 | E27: -250 | F27: 0
B28: Sale and Repurchase Agreement Growth Rate | C28: % | D28: 0 | E28: 0 | F28: 0
B30: Retail Deposit Spread | C30: % | D30: 0 | E30: 0 | F30: 0
B31: Short-term borrowing spread | C31: % | D31: 0.006 | E31: 0.006 | F31: 0.006
B32: Covered bond spread | C32: % | D32: 0.006 | E32: 0.006 | F32: 0.006
B33: Corporate bond rate | C33: % | D33: 0.0525 | E33: 0.065 | F33: 0.065
B34: Repo Spread | C34: % | D34: 0.0047 | E34: 0.0047 | F34: 0.0047
B35: ILTR Spread | C35: % | D35: 0.0015 | E35: 0.0015 | F35: 0.0015
B37: Asset yield / NII assumptions
B39: Mortgage asset spread | C39: % | D39: 0.025 | E39: 0.025 | F39: 0.025
B40: Mortgage asset yield | C40: % | D40: =D9+0.025 -> 0.0663 | E40: =E9+0.025 -> 0.0727 | F40: =F9+0.025 -> 0.0675
B41: Commercial asset spread | C41: % | D41: 0.06 | E41: 0.06 | F41: 0.06
B42: Commercial asset yield | C42: % | D42: =D41+D9 -> 0.1013 | E42: =E41+E9 -> 0.1077 | F42: =F41+F9 -> 0.1025
B43: Cash/reserves spread | C43: % | D43: -0.001 | E43: -0.001 | F43: -0.001
B44: Investment securities spread | C44: % | D44: 0.01 | E44: 0.01 | F44: 0.01
B46: Credit Performance Assumptions
B48: Mortgage cost of risk | C48: bps | D48: 10 | E48: 10 | F48: 10
B49: Commercial cost of risk | C49: bps | D49: 90 | E49: 90 | F49: 90
B51: Depreciation, PP&E and Amortization
B53: Useful life of PP&E | C53: years | D53: 5 | E53: 5 | F53: 5
B54: Capital Expenditure Growth Rate | C54: % | D54: 0.03 | E54: 0.03 | F54: 0.03
...

Sheet Model
B2: =Cover!$B$2 -> Paragon Bank
B3: Financial Statements - Income Statement
C7: Units / £m | E7: 2024 | F7: 2025 | G7: =F7+1 -> 2026 | H7: =G7+1 -> 2027 | I7: =H7+1 -> 2028
B9: Interest Receivable | E9: 1314.7 | F9: 1249 | G9: =G215 -> 1311.3767 | H9: =H215 -> 1535.5872 | I9: =I215 -> 1457.6103
B10: Interest Payable | E10: -831.5 | F10: -746.7 | G10: =-G245 -> -771.3949 | H10: =-H245 -> -932.95911 | I10: =-I245 -> -842.38931
B11: Net Interest Income | E11: =SUM(E9:E10) -> 483.2 | F11: =SUM(F9:F10) -> 502.3 | G11: =SUM(G9:G10) -> 539.9818 | H11: =SUM(H9:H10) -> 602.62808 | I11: =SUM(I9:I10) -> 615.22098
B13: Other leasing income | E13: 30.4 | F13: 31.7 | G13: =G401 -> 32.651 | H13: =H401 -> 33.63053 | I13: =I401 -> 34.639446
B14: Related costs | E14: -24.2 | F14: -25.6 | G14: =G402 -> -26.368 | H14: =H402 -> -27.15904 | I14: =I402 -> -27.973811
B15: Net operating lease income | E15: =SUM(E13:E14) -> 6.2 | F15: =SUM(F13:F14) -> 6.1 | G15: =SUM(G13:G14) -> 6.283 | H15: =SUM(H13:H14) -> 6.47149 | I15: =SUM(I13:I14) -> 6.6656347
B16: Other income | E16: 7 | F16: 6.7 | G16: =G404 -> 6.7 | H16: =H404 -> 6.7 | I16: =I404 -> 6.7
B17: Other operating income | E17: =SUM(E15:E16) -> 13.2 | F17: =SUM(F15:F16) -> 12.8 | G17: =SUM(G15:G16) -> 12.983 | H17: =SUM(H15:H16) -> 13.17149 | I17: =SUM(I15:I16) -> 13.365635
B19: Total Operating Income | E19: =E11+E17 -> 496.4 | F19: =F11+F17 -> 515.1 | G19: =G11+G17 -> 552.9648 | H19: =H11+H17 -> 615.79957 | I19: =I11+I17 -> 628.58661
B21: Operating expenses | E21: -179.2 | F21: -179.3 | G21: =-G415 -> -200.86851 | H21: =-H415 -> -213.8555 | I21: =-I415 -> -227.24246
B22: Provisions for credit losses | E22: -24.5 | F22: -41.9 | G22: =-G318 -> -37.051584 | H22: =-H318 -> -39.173575 | I22: =-I318 -> -41.555655
B23: Provisions for liabilties | E23: 0 | F23: -25.5 | G23: =Assumptions!D67 -> 0 | H23: =Assumptions!E67 -> 0 | I23: =Assumptions!F67 -> 0
B24: Operating profit before fair value items | E24: =E19+SUM(E21:E23) -> 292.7 | F24: =F19+SUM(F21:F23) -> 268.4 | G24: =G19+SUM(G21:G23) -> 315.04471 | H24: =H19+SUM(H21:H23) -> 362.7705 | I24: =I19+SUM(I21:I23) -> 359.7885
B25: Fair value net (losses) | E25: -38.9 | F25: -11.9 | G25: =Assumptions!D68 -> 0 | H25: =Assumptions!E68 -> 0 | I25: =Assumptions!F68 -> 0
B26: Operating Profit on ordinary activities before taxation | E26: =SUM(E24:E25) -> 253.8 | F26: =SUM(F24:F25) -> 256.5 | G26: =SUM(G24:G25) -> 315.04471 | H26: =SUM(H24:H25) -> 362.7705 | I26: =SUM(I24:I25) -> 359.7885
B27: Tax charge on profit on ordinary activities | E27: -67.8 | F27: -76.2 | G27: =G26*-Assumptions!D69 -> -86.637295 | H27: =H26*-Assumptions!E69 -> -99.761887 | I27: =I26*-Assumptions!F69 -> -98.941836
B28: Profit on ordinary activities after taxation | E28: =SUM(E26:E27) -> 186 | F28: =SUM(F26:F27) -> 180.3 | G28: =SUM(G26:G27) -> 228.40741 | H28: =SUM(H26:H27) -> 263.00861 | I28: =SUM(I26:I27) -> 260.84666
B31: Earning per share | C31: Units / pence
B32: - Basic | E32: 88.5 | F32: 91.2
B33: - Diluted | E33: 85.2 | F33: 87.9
B36: Margin/Ratios
B38: Revenue Growth | C38: % | F38: =(F9-E9)/E9 -> -0.049973378 | G38: =(G9-F9)/F9 -> 0.049941311 | H38: =(H9-G9)/G9 -> 0.17097337 | I38: =(I9-H9)/H9 -> -0.050779867
B39: Cost-to-income ratio | C39: % | E39: =ABS(E21)/E19 -> 0.36099919 | F39: =ABS(F21)/F19 -> 0.34808775 | G39: =ABS(G21)/G19 -> 0.36325732 | H39: =ABS(H21)/H19 -> 0.34728101 | I39: =ABS(I21)/I19 -> 0.36151336
B40: Pre-provision operating margin | C40: % | E40: =E24/E19 -> 0.58964545 | F40: =F24/F19 -> 0.52106387 | G40: =G24/G19 -> 0.56973736 | H40: =H24/H19 -> 0.58910482 | I40: =I24/I19 -> 0.57237697
B47: =Cover!$B$2 -> Paragon Bank
B48: Financial Statements - Balance Sheet
C52: Units / £m | E52: 2024 | F52: 2025 | G52: =F52+1 -> 2026 | H52: =G52+1 -> 2027 | I52: =H52+1 -> 2028
B53: Assets
B54: Cash - central bank | E54: 2315.5 | F54: 2175.7 | G54: =G88-SUM(G55:G63) -> 3019.5961 | H54: =H88-SUM(H55:H63) -> 2251.6373 | I54: =I88-SUM(I55:I63) -> 1975.6534
B55: Cash - retail bank | E55: 209.9 | F55: 213.8 | G55: =F55 -> 213.8 | H55: =G55 -> 213.8 | I55: =H55 -> 213.8
B56: Investment securities | E56: 427.4 | F56: 626.2 | G56: =F56 -> 626.2 | H56: =G56 -> 626.2 | I56: =H56 -> 626.2
B57: Loans to customers | E57: 15630.3 | F57: 16335.9 | G57: =G123 -> 16999.808 | H57: =H123 -> 17760.305 | I57: =I123 -> 18622.815
B58: Derivative financial assets | E58: 391.8 | F58: 275.4 | G58: =F58 -> 275.4 | H58: =G58 -> 275.4 | I58: =H58 -> 275.4
B59: Sundry assets | E59: 20.7 | F59: 24.2 | G59: =F59*(1+G38) -> 25.40858 | H59: =G59*(1+H38) -> 29.75277 | I59: =H59*(1+I38) -> 28.241929
B60: Current tax assets | E60: 9.7 | F60: 6.2 | G60: =F60 -> 6.2 | H60: =G60 -> 6.2 | I60: =H60 -> 6.2
B61: Retirement benefit obligations | E61: 22.2 | F61: 23.5 | G61: =F61 -> 23.5 | H61: =G61 -> 23.5 | I61: =H61 -> 23.5
B62: Property, plant and equipment | E62: 71 | F62: 77 | G62: =G362 -> 81.5896 | H62: =H362 -> 81.760088 | I62: =I362 -> 77.378891
...
