Workbook

Sheet Cover
B2: Solid State PLC
B4: Modelled by Peter Hopkinson
B5: =DATE(2026, 10, 14) -> 46309

Sheet Assumptions
B2: =Cover!$B$2 -> Solid State PLC
B3: Assumptions | L3: ="Currently Running: "&CHOOSE(Assumptions!$B$10,Assumptions!$F$15,Assumptions!$F$16,Assumptions!$F$17)&"Scenario" -> Currently Running: Upside Scenario
F5: Fiscal Years Ending December 31
F6: 2025 | G6: =F6+1 -> 2026 | H6: =G6+1 -> 2027 | I6: =H6+1 -> 2028 | J6: =I6+1 -> 2029 | K6: =J6+1 -> 2030 | L6: =K6+1 -> 2031
B7: (£m in millions) | F7: H = Historical | L7: F = Forecast
B9: Scenario Selector:
B10: 2
B12: Macro Assumptions
B14: Inflation | F14: Selected | H14: =CHOOSE($B$10,H15,H16,H17) -> 0.03 | I14: =CHOOSE($B$10,I15,I16,I17) -> 0.03 | J14: =CHOOSE($B$10,J15,J16,J17) -> 0.03 | K14: =CHOOSE($B$10,K15,K16,K17) -> 0.03 | L14: =CHOOSE($B$10,L15,L16,L17) -> 0.03
F15: Base | H15: 0.04 | I15: 0.04 | J15: 0.035 | K15: 0.03 | L15: 0.03
F16: Upside | H16: 0.03 | I16: 0.03 | J16: 0.03 | K16: 0.03 | L16: 0.03
F17: Downside | H17: 0.04 | I17: 0.045 | J17: 0.045 | K17: 0.04 | L17: 0.03
B19: Wage Inflation | F19: Selected | H19: =CHOOSE($B$10,H20,H21,H22) -> 0.03 | I19: =CHOOSE($B$10,I20,I21,I22) -> 0.03 | J19: =CHOOSE($B$10,J20,J21,J22) -> 0.03 | K19: =CHOOSE($B$10,K20,K21,K22) -> 0.03 | L19: =CHOOSE($B$10,L20,L21,L22) -> 0.03
F20: Base | H20: 0.04 | I20: 0.04 | J20: 0.035 | K20: 0.03 | L20: 0.03
F21: Upside | H21: 0.03 | I21: 0.03 | J21: 0.03 | K21: 0.03 | L21: 0.03
F22: Downside | H22: 0.04 | I22: 0.045 | J22: 0.045 | K22: 0.04 | L22: 0.03
B24: Overhead Inflation | F24: Selected | H24: =CHOOSE($B$10,H25,H26,H27) -> 0.03 | I24: =CHOOSE($B$10,I25,I26,I27) -> 0.03 | J24: =CHOOSE($B$10,J25,J26,J27) -> 0.03 | K24: =CHOOSE($B$10,K25,K26,K27) -> 0.03 | L24: =CHOOSE($B$10,L25,L26,L27) -> 0.03
F25: Base | H25: 0.04 | I25: 0.04 | J25: 0.035 | K25: 0.03 | L25: 0.03
F26: Upside | H26: 0.03 | I26: 0.03 | J26: 0.03 | K26: 0.03 | L26: 0.03
F27: Downside | H27: 0.04 | I27: 0.045 | J27: 0.045 | K27: 0.04 | L27: 0.03
B30: Revenue Assumptions
B33: Volume Growth - Communications | F33: Selected | H33: =CHOOSE($B$10,H34,H35,H36) -> 0.03 | I33: =CHOOSE($B$10,I34,I35,I36) -> 0.03 | J33: =CHOOSE($B$10,J34,J35,J36) -> 0.03 | K33: =CHOOSE($B$10,K34,K35,K36) -> 0.03 | L33: =CHOOSE($B$10,L34,L35,L36) -> 0.03
F34: Base | H34: 0.02 | I34: 0.02 | J34: 0.02 | K34: 0.02 | L34: 0.02
F35: Upside | H35: 0.03 | I35: 0.03 | J35: 0.03 | K35: 0.03 | L35: 0.03
F36: Downside | H36: -0.01 | I36: -0.005 | J36: 0 | K36: 0.01 | L36: 0.01
B38: Volume Growth - Power | F38: Selected | H38: =CHOOSE($B$10,H39,H40,H41) -> 0.1 | I38: =CHOOSE($B$10,I39,I40,I41) -> 0.1 | J38: =CHOOSE($B$10,J39,J40,J41) -> 0.09 | K38: =CHOOSE($B$10,K39,K40,K41) -> 0.08 | L38: =CHOOSE($B$10,L39,L40,L41) -> 0.08
F39: Base | H39: 0.08 | I39: 0.08 | J39: 0.08 | K39: 0.075 | L39: 0.075
F40: Upside | H40: 0.1 | I40: 0.1 | J40: 0.09 | K40: 0.08 | L40: 0.08
F41: Downside | H41: 0.03 | I41: 0.03 | J41: 0.03 | K41: 0.03 | L41: 0.03
B43: Volume Growth - Computing | F43: Selected | H43: =CHOOSE($B$10,H44,H45,H46) -> 0.04 | I43: =CHOOSE($B$10,I44,I45,I46) -> 0.04 | J43: =CHOOSE($B$10,J44,J45,J46) -> 0.035 | K43: =CHOOSE($B$10,K44,K45,K46) -> 0.035 | L43: =CHOOSE($B$10,L44,L45,L46) -> 0.04
F44: Base | H44: 0.03 | I44: 0.03 | J44: 0.03 | K44: 0.03 | L44: 0.03
F45: Upside | H45: 0.04 | I45: 0.04 | J45: 0.035 | K45: 0.035 | L45: 0.04
F46: Downside | H46: -0.01 | I46: -0.005 | J46: 0 | K46: 0.01 | L46: 0.01
B48: Volume Growth - Electronics | F48: Selected | H48: =CHOOSE($B$10,H49,H50,H51) -> 0.09 | I48: =CHOOSE($B$10,I49,I50,I51) -> 0.08 | J48: =CHOOSE($B$10,J49,J50,J51) -> 0.075 | K48: =CHOOSE($B$10,K49,K50,K51) -> 0.07 | L48: =CHOOSE($B$10,L49,L50,L51) -> 0.065
F49: Base | H49: 0.06 | I49: 0.06 | J49: 0.055 | K49: 0.05 | L49: 0.05
F50: Upside | H50: 0.09 | I50: 0.08 | J50: 0.075 | K50: 0.07 | L50: 0.065
F51: Downside | H51: 0.02 | I51: 0.02 | J51: 0.02 | K51: 0.02 | L51: 0.02

Sheet Model
B3: =Cover!$B$2 -> Solid State PLC
B4: Financial Statements - Income Statement | L4: ="Currently Running: "&CHOOSE(Assumptions!$B$10,Assumptions!$F$15,Assumptions!$F$16,Assumptions!$F$17)&"Scenario" -> Currently Running: Upside Scenario
F6: Fiscal Years Ending December 31
F7: 2025 | G7: 2026 | H7: =G7+1 -> 2027 | I7: =H7+1 -> 2028 | J7: =I7+1 -> 2029 | K7: =J7+1 -> 2030 | L7: =K7+1 -> 2031
B8: (£ in 000s) | F8: H = Historical | L8: F = Forecast
B10: Revenue | F10: 125064 | G10: 154144 | H10: =H231 -> 152272.39 | I10: =I231 -> 158508.23 | J10: =J231 -> 173337.27 | K10: =K231 -> 188771.53 | L10: =L231 -> 205330.42
B11: Cost of Sales | F11: -85737 | G11: -102528 | H11: =-H293 -> -93965.271 | I11: =-I293 -> -103045.85 | J11: =-J293 -> -112542.75 | K11: =-K293 -> -122449.69 | L11: =-L293 -> -133046.03
B12: Gross profit | F12: =SUM(F10:F11) -> 39327 | G12: =SUM(G10:G11) -> 51616 | H12: =SUM(H10:H11) -> 58307.121 | I12: =SUM(I10:I11) -> 55462.386 | J12: =SUM(J10:J11) -> 60794.525 | K12: =SUM(K10:K11) -> 66321.841 | L12: =SUM(L10:L11) -> 72284.384
B13: Gross profit margin | F13: =F12/F10 -> 0.314455 | G13: =G12/G10 -> 0.33485572 | H13: =H12/H10 -> 0.38291328 | I13: =I12/I10 -> 0.34990224 | J13: =J12/J10 -> 0.35072967 | K13: =K12/K10 -> 0.35133391 | L13: =L12/L10 -> 0.35203934
B15: Sales, general and administrative expenses | F15: -37993 | G15: -44669 | H15: =-H303 -> -46009.07 | I15: =-I303 -> -49135.957 | J15: =-J303 -> -54871.318 | K15: =-K303 -> -61046.631 | L15: =-L303 -> -67842.079
B16: EBIT | F16: =SUM(F15:F15)+F12 -> 1334 | G16: =SUM(G15:G15)+G12 -> 6947 | H16: =SUM(H15:H15)+H12 -> 12298.051 | I16: =SUM(I15:I15)+I12 -> 6326.4293 | J16: =SUM(J15:J15)+J12 -> 5923.2071 | K16: =SUM(K15:K15)+K12 -> 5275.21 | L16: =SUM(L15:L15)+L12 -> 4442.3052
B17: EBIT Margin | F17: =F16/F10 -> 0.010666539 | G17: =G16/G10 -> 0.045068248 | H17: =H16/H10 -> 0.0807635 | I17: =I16/I10 -> 0.039912307 | J17: =J16/J10 -> 0.034171572 | K17: =K16/K10 -> 0.027944945 | L17: =L16/L10 -> 0.021634911
B19: Depreciation of PP&E | H19: =-H428 -> -780.05877 | I19: =-I428 -> -1075.3004 | J19: =-J428 -> -1390.5536 | K19: =-K428 -> -1734.557 | L19: =-L428 -> -2108.9538
B20: Depreciation of ROU assets | H20: =-H373 -> -1262.6 | I20: =-I373 -> -1612.6 | J20: =-J373 -> -2012.6 | K20: =-K373 -> -2412.6 | L20: =-L373 -> -2812.6
B21: Amortisation | H21: =-H452 -> -1714.4724 | I21: =-I452 -> -2025.253 | J21: =-J452 -> -2357.0985 | K21: =-K452 -> -2719.2073 | L21: =-L452 -> -3113.3093
B22: Depreciation and Amortization | H22: =SUM(H19:H21) -> -3757.1312 | I22: =SUM(I19:I21) -> -4713.1534 | J22: =SUM(J19:J21) -> -5760.2521 | K22: =SUM(K19:K21) -> -6866.3643 | L22: =SUM(L19:L21) -> -8034.8631
B23: EBITDA | F23: =F16-F22 -> 1334 | G23: =G16-G22 -> 6947 | H23: =H16-H22 -> 16055.183 | I23: =I16-I22 -> 11039.583 | J23: =J16-J22 -> 11683.459 | K23: =K16-K22 -> 12141.574 | L23: =L16-L22 -> 12477.168
B24: EBITDA Margin | F24: =F23/F10 -> 0.010666539 | G24: =G23/G10 -> 0.045068248 | H24: =H23/H10 -> 0.10543725 | I24: =I23/I10 -> 0.069646746 | J24: =J23/J10 -> 0.06740304 | K24: =K23/K10 -> 0.064318884 | L24: =L23/L10 -> 0.060766293
B26: Finance expense | F26: -1014 | G26: -1102 | H26: =H513-H507+H387 -> -1195.938 | I26: =I513-I507+I387 -> -467.06639 | J26: =J513-J507+J387 -> -530.69604 | K26: =K513-K507+K387 -> -599.46854 | L26: =L513-L507+L387 -> -667.64124
B27: Net finance costs | F27: =SUM(F26:F26) -> -1014 | G27: =SUM(G26:G26) -> -1102 | H27: =SUM(H26:H26) -> -1195.938 | I27: =SUM(I26:I26) -> -467.06639 | J27: =SUM(J26:J26) -> -530.69604 | K27: =SUM(K26:K26) -> -599.46854 | L27: =SUM(L26:L26) -> -667.64124
B29: Profit before tax | F29: =F16+F27 -> 320 | G29: =G16+G27 -> 5845 | H29: =H16+H27 -> 11102.113 | I29: =I16+I27 -> 5859.363 | J29: =J16+J27 -> 5392.511 | K29: =K16+K27 -> 4675.7414 | L29: =L16+L27 -> 3774.664
B31: Tax (expense)/credit | F31: 192 | G31: -1757 | H31: =-H537 -> -3330.634 | I31: =-I537 -> -1757.8089 | J31: =-J537 -> -1617.7533 | K31: =-K537 -> -1402.7224 | L31: =-L537 -> -1132.3992
B32: Net Profit | F32: =F29+F31 -> 512 | G32: =G29+G31 -> 4088 | H32: =H29+H31 -> 7771.4793 | I32: =I29+I31 -> 4101.5541 | J32: =J29+J31 -> 3774.7577 | K32: =K29+K31 -> 3273.019 | L32: =L29+L31 -> 2642.2648
B33: Net Profit Margin | F33: =F32/F10 -> 0.0040939039 | G33: =G32/G10 -> 0.026520656 | H33: =H32/H10 -> 0.051036693 | I33: =I32/I10 -> 0.025875968 | J33: =J32/J10 -> 0.021776953 | K33: =K32/K10 -> 0.01733852 | L33: =L32/L10 -> 0.012868355
B35: Earning per share
B36: - Basic | D36: pence per share | F36: 0.9 | G36: 7.2 | H36: =(H32*1000/$D$38)*100 -> 13.615065 | I36: =(I32*1000/$D$38)*100 -> 7.1856238 | J36: =(J32*1000/$D$38)*100 -> 6.6131004 | K36: =(K32*1000/$D$38)*100 -> 5.7340907 | L36: =(L32*1000/$D$38)*100 -> 4.6290554
B38: Shares Trading | D38: 57080000
B42: =Cover!$B$2 -> Solid State PLC
B43: Financial Statements - Balance Sheet | L43: ="Currently Running: "&CHOOSE(Assumptions!$B$10,Assumptions!$F$15,Assumptions!$F$16,Assumptions!$F$17)&"Scenario" -> Currently Running: Upside Scenario
F45: Fiscal Years Ending December 31
F46: 2025 | G46: 2026 | H46: =G46+1 -> 2027 | I46: =H46+1 -> 2028 | J46: =I46+1 -> 2029 | K46: =J46+1 -> 2030 | L46: =K46+1 -> 2031
B47: (£ in 000s) | F47: H = Historical | L47: F = Forecast
B49: Assets
B51: Inventories | F51: 28239 | G51: 30502 | H51: =H324 -> 27954.595 | I51: =I324 -> 30656.06 | J51: =J324 -> 33481.38 | K51: =K324 -> 36428.687 | L51: =L324 -> 39581.091
B52: Trade and other receivables | F52: 21616 | G52: 20157 | H52: =H323 -> 19912.255 | I52: =I323 -> 20727.699 | J52: =J323 -> 22666.853 | K52: =K323 -> 24685.15 | L52: =L323 -> 26850.511
B53: Corporation tax asset | F53: 986 | G53: 2392 | H53: =IF(H547>0, H547, 0) -> 0 | I53: =IF(I547>0, I547, 0) -> 0 | J53: =IF(J547>0, J547, 0) -> 0 | K53: =IF(K547>0, K547, 0) -> 0 | L53: =IF(L547>0, L547, 0) -> 0
B54: Cash and cash equivalents | F54: 3513 | G54: 6568 | H54: =H132 -> 3897.1818 | I54: =I132 -> 3956.7221 | J54: =J132 -> 3654.4073 | K54: =K132 -> 3641.7662 | L54: =L132 -> 3785.1186
B55: Current Assets | F55: =SUM(F51:F54) -> 54354 | G55: =SUM(G51:G54) -> 59619 | H55: =SUM(H51:H54) -> 51764.031 | I55: =SUM(I51:I54) -> 55340.481 | J55: =SUM(J51:J54) -> 59802.64 | K55: =SUM(K51:K54) -> 64755.603 | L55: =SUM(L51:L54) -> 70216.721
B56: PP&E, gross
B57: (-) Accumulated depreciation
...
